Workbook

Sheet DATOS
A2: NOMBRE DE TALLER | B2: CARRIGAS PERU E.I.R.L.
A3: DIRECCION DE TALLER | B3: AV. HUANCARAY MZA. I LOTE. 15 URB. SANTA CRUZ - SANTA ANITA
A4: RUC | B4: 20609224941
A5: TELEFONO | B5: 971065262
A8: NOMBRE DEL SOLICITANTE / RAZON SOCIAL | B8: VASQUEZ VILLARREAL ALEX ANTONIO
A9: RUC (PARA PJ)
A10: DIRECCION | B10: JR QUILCA 571 TDA 108
A11: DISTRITO/PROVINCIA/DEPARTAMENTO | B11: LIMA / LIMA / LIMA
A12: DNI/CE | B12: 73514426
A13: REPRESENTANTE LEGAL (NOMBRES Y APELLIDOS)
A14: DNI REP. LEGAL
A15: CELULAR | B15: 931580291
A16: MARCA Y MODELO | B16: JETOUR X50
A17: MARCA | B17: JETOUR
A18: MODELO | B18: X50
A19: AÑO | B19: 2027
A20: PLACA | B20: CYB612
A21: COLOR | B21: GRIS | D21: BI-COMBUSTIBLE GLP
A22: COMBUSTIBLE ACTUAL | B22: GASOLINA | D22: GASOLINA
A23: CILINDRADA | B23: 1.499
A24: CATEGORIA | B24: M1
A25: Fecha Fabricación Cilindro: | C25: =DAY(B25) -> 0 | D25: =TEXT(B25,"mmmm") -> Enero | E25: =YEAR(B25) -> 1900
A26: CANTIDAD DE CILINDROS | B26: 2
A27: UBICACIÓN DE CILINDRO | B27: MALETERA
A28: CAPACIDAD DE CILINDRO | B28: 28+28
A29: GALONES | B29: 2+2 | F29: 2+2
A30: LITROS | B30: 28+28 | D30: BRC | E30: 3 Y 3
A31: Kit GNV/Marca: 5TA | B31: TOMASETTO ACHILLE
A32: PRECIO DE CONVERSION | B32: 5300
A33: DESCUENTO GLP
A34: KILOMETRAJE | B34: 1432
A35: CORREO | B35: alexvasquez112001@gmail.com | C35: º
A36: RESPONSABLE DE CONVERSION | B36: HENRY ALBERTO CHAVEZ MEDINA | E36: }
A38: TANQUE
A39: SERIE
A40: PRODUCE
A42: REDUCTOR
A43: SERIE
A44: PRODUCE
A45: FECHA DE VENCIMIENTO GARANTIA | B45: 46499
...

Sheet PROF.
B4: PROFORMA DE CONVERSIÓN FISE GNV
B6: DATOS DEL TALLER FECHA________
B7: Nombre del taller: | C7: =DATOS!B2 -> CARRIGAS PERU E.I.R.L. | F7: RUC: | G7: =DATOS!B4 -> 20609224941
B8: Dirección del taller: | C8: =DATOS!B3 -> AV. HUANCARAY MZA. I LOTE. 15 URB. SANTA CRUZ - SANTA ANITA | F8: Teléfono: | G8: =DATOS!B5 -> 971065262
B9: DATOS SOLICITANTE Y DEL VEHÍCULO (datos de la tarjeta de propiedad)
B10: Nombre del solicitante: | C10: =DATOS!B8 -> VASQUEZ VILLARREAL ALEX ANTONIO | G10: DNI / CE: | H10: =DATOS!B12 -> 73514426
B11: Dirección del solicitante: | C11: =DATOS!B10 -> JR QUILCA 571 TDA 108 | G11: Teléfono: | H11: =DATOS!B15 -> 931580291
B12: Marca y Modelo: | C12: =DATOS!B16 -> JETOUR X50 | D12: Año: | E12: =DATOS!B19 -> 2027 | F12: Placa: | G12: =DATOS!B20 -> CYB612 | H12: Color: | I12: =DATOS!B21 -> GRIS
B13: Combustible actual: | C13: =DATOS!B22 -> GASOLINA | F13: Cilindrada: | G13: =DATOS!B23 -> 1.499 | H13: Categoría: | I13: =DATOS!B24 -> M1
B14: PROFORMA DE CONVERSIÓN
B15: Cantidad de Cilindros GNV: | D15: Fecha Fabricación Cilindro: | H15: Ubicación de cilindro:
B16: =DATOS!B26 -> 2 | H16: =+DATOS!B27 -> MALETERA
B17: Kit GNV/Marca: 5TA | C17: =DATOS!B31 -> TOMASETTO ACHILLE | D17: Capacidad Cilindro GNV: | F17: 2+2 | G17: Galones | H17: =DATOS!B30 -> 28+28 | I17: Lts.
B18: Precio total del Servicio de conversión vehicular: | F18: Servicios adicionales (sin costo) al servicio de conversión vehicular:
B19: =+DATOS!B32 -> 5300 | F19: vehicular: | G19: ---------------------
B21: PREINSPECCIÓN
B22: Kilometraje real: | C22: =DATOS!B34 -> 1432 | F22: Fecha: | G22: 46134
B23: REVISIONES (Conforme marca S o N)
B24: 1. Batería arranque | D24: S N | F24: 5. Sistema de escape | I24: S N
B25: 2. Bobina/ cableado / bujías | D25: S N | F25: 6. Sistema de enfriamiento | I25: S N
B26: 3. Sistema de inyección | D26: S N | F26: 7. Sistema eléctrico | I26: S N
B27: 4. Sistema de admisión | D27: S N | F27: 8. Carrocería y chasis | I27: S N
B28: 9. Verificación de balance y compresión de cilindros:
B29: Número de cilindros del motor 1 2 3 4 5 6 7 8
B30: Compresión obtenida ( se sugiere que no sea menos de 130 psi):
B31: 10. Verificación de sistemas con escáner automotriz S N
B32: RESULTADO DE LAS REVISIONES
B33: Resultado general (Aprobado/No aprobado): | D33: Nombre del responsable de la revisión: | H33: V° B° o firma
B34: Aprobado | D34: HENRY ALBERTO CHAVEZ MEDINA
B35: Vehículo apto para conversión mediante kit de conversión de quinta generación
B36: Observaciones:

Sheet DECLARACIÒN.
B4: DECLARACION JURADA DE ENTREGA KIT GLP
B6: Yo | C6: =_xlfn.CONCAT(DATOS!B8,", ") -> VASQUEZ VILLARREAL ALEX ANTONIO, | H6: identificado con DNI N.º | K6: =_xlfn.CONCAT(DATOS!B12,",") -> 73514426,
B7: en mi calidad de Propietario del Vehículo de Placa: | H7: =DATOS!B20 -> CYB612
B9: DECLARO BAJO JURAMENTO:
C11: =_xlfn.CONCAT("1.") -> 1. | D11: =_xlfn.CONCAT("Que el día ",DATOS!C25," de ",DATOS!D25," de ",DATOS!E25,", he entregado correctamente el kit de conversión a GLP, financiado a través del") -> Que el día 0 de Enero de 1900, he entregado correctamente el kit de conversión a GLP, financiado a través del
D12: =_xlfn.CONCAT("Programa FISE, correspondiente al siguiente vehículo:") -> Programa FISE, correspondiente al siguiente vehículo:
D14: o | E14: Placa: | F14: =H7 -> CYB612
D15: o | E15: Marca: | F15: =DATOS!B17 -> JETOUR
D16: o | E16: Modelo: | F16: =DATOS!B18 -> X50
D17: o | E17: Año: | F17: =DATOS!B19 -> 2027
C19: =_xlfn.CONCAT("2.") -> 2. | D19: Que el kit de GLP entregado está compuesto como mínimo por los siguientes elementos:
D21: Cilindro de GLP | H21: Computadora (No aplica 3era)
D22: Multiválvula | H22: Regulador de presión
D23: Válvula de carga | H23: Conmutador
D24: Riel de inyectores (No aplica 3era) | H24: Filtro de Gas
D25: Sensor de Nivel | H25: Tuberías y accesorios
D26: Ramal eléctrico (No aplica 3era)
C28: =_xlfn.CONCAT("3.") -> 3. | D28: Que el kit ha sido entregado en condiciones operativas, y conforme a la normativa técnica vigente, y exclusivamente para efectos del acceso al beneficio del Fondo de Inclusión Social Energético (FISE) en el proceso de conversión a Gas Natural Vehicular (GNV).
C32: =_xlfn.CONCAT("4.") -> 4. | D32: Que declaro bajo juramento que la información consignada en la presente Declaración Jurada es verdadera, completa, exacta y verificable, asumiendo plena responsabilidad por su contenido.
C35: =_xlfn.CONCAT("5.") -> 5. | D35: Asimismo, tengo conocimiento que la omisión, falsedad o inexactitud de la información declarada da lugar a responsabilidad administrativa, civil y penal, conforme a lo dispuesto en el artículo 411 del Código Penal, sin perjuicio de las acciones que correspondan al Fondo de Inclusión Social Energético – FISE, el cual se encuentra facultado a realizar acciones de verificación y control posterior.
B39: Firmo la presente declaración jurada en señal de conformidad.
C42: Reductor GLP | F42: Marca | H42: Serie
F43: =DATOS!B17 -> JETOUR | H43: =DATOS!B43 -> 0
C44: Cilindro de GLP | F44: Marca/Capacidad/Año Fabricación | H44: Serie
F45: =_xlfn.CONCAT(F43," / ",DATOS!B28," / ",DATOS!B19) -> JETOUR / 28+28 / 2027 | H45: =DATOS!B39 -> 0

Sheet COND. DE DEVOLUCION PN
B2: CONDICIONES PARA LA DEVOLUCIÓN DEL FINANCIAMIENTO GNV | H2: N° 2284- | I2: 0234
B26: FINANCIAMIENTO GNV | D26: MONTO
B27: Costo del servicio de conversión a GNV (incluye IGV) | D27: =DATOS!B32 -> 5300
B28: Costo de certificación (Incluye IGV) | D28: Subsidiado
B29: Total Financiado | D29: =SUM(D27:D28) -> 5300
B33: DEVOLUCIÓN | C33: Descuento o subvención sobre el total financiado | D33: Monto total a devolver
C34: =DATOS!B33 -> 0 | D34: =D29-C34 -> 5300
C35: Factor de recaudación | D35: Número de cuotas mensuales
C36: Según consumo (Valor mínimo =50%) | D36: 36
F38: DATOS DEL BENEFICIARIO GNV:
F39: NOMBRES Y APELLIDOS | G39: =DATOS!B8 -> VASQUEZ VILLARREAL ALEX ANTONIO
F40: DNI | G40: =DATOS!B12 -> 73514426
F41: DIRECCIÓN | G41: =DATOS!B10 -> JR QUILCA 571 TDA 108
F42: DISTRITO/PROVINCIA/ DEPARTAMENTO | G42: =DATOS!B11 -> LIMA / LIMA / LIMA
F43: TELÉFONO/ CELULAR | G43: =DATOS!B15 -> 931580291
F44: CORREO ELECTRÓNICO | G44: =+DATOS!B35 -> alexvasquez112001@gmail.com
F45: PLACA DEL VEHÍCULO | G45: =DATOS!B20 -> CYB612
F46: FECHA DE FIRMA | G46: =DATOS!B25 -> 0
G53: BENEFICIARIO GNV

Sheet COND. DE DEVOLUCION PJ
B2: CONDICIONES PARA LA DEVOLUCIÓN DEL FINANCIAMIENTO GNV | H2: N° 2284- | J2: 0034
B26: FINANCIAMIENTO GNV | D26: MONTO
B27: Costo del servicio de conversión a GNV (incluye IGV) | D27: =DATOS!B32 -> 5300
B28: Costo del servicio de certificación (Incluye IGV) | D28: Subsidiado
B29: Total Financiado | D29: =SUM(D27:D28) -> 5300
B33: DEVOLUCIÓN | C33: Descuento o subvención sobre el total financiado | D33: Monto total a devolver
C34: No asignado a personas jurídicas
C35: Factor de recaudación | D35: Número de cuotas mensuales
C36: Según consumo (Valor mínimo =50%) | D36: 36
F38: DATOS DEL BENEFICIARIO GNV:
F39: RAZÓN SOCIAL | G39: =DATOS!B8 -> VASQUEZ VILLARREAL ALEX ANTONIO | I39: R.U.C. | J39: =+DATOS!B9 -> 0
F40: REPRESENTANTE LEGAL (NOMBRES Y APELLIDOS) | G40: =+DATOS!B13 -> 0 | I40: D.N.I. | J40: =+DATOS!B14 -> 0
F41: DIRECCIÓN FISCAL | G41: =DATOS!B10 -> JR QUILCA 571 TDA 108
F42: DISTRITO/PROVINCIA/ DEPARTAMENTO | G42: =DATOS!B11 -> LIMA / LIMA / LIMA
F43: TELÉFONO/ CELULAR | G43: =DATOS!B15 -> 931580291
F44: CORREO ELECTRÓNICO | G44: =+DATOS!B35 -> alexvasquez112001@gmail.com
F45: PLACA | G45: =DATOS!B20 -> CYB612
F46: FECHA DE FIRMA | G46: =DATOS!B25 -> 0
G53: BENEFICIARIO GNV

Sheet CHECK
B5: TALLER DE CONVERSION
B6: Nombre: | C6: =DATOS!B2 -> CARRIGAS PERU E.I.R.L. | J6: GLP
B7: Dirección: | C7: =DATOS!B3 -> AV. HUANCARAY MZA. I LOTE. 15 URB. SANTA CRUZ - SANTA ANITA | J7: GNV | K7: X
B8: Teléfono: | C8: =DATOS!B5 -> 971065262
B9: PROPIETARIO | F9: VEHICULO
B10: Nombre: | C10: =DATOS!B8 -> VASQUEZ VILLARREAL ALEX ANTONIO | F10: Marca y Año: | H10: =DATOS!B16 -> JETOUR X50
B11: Identificación (DNI Y/O RUC): | D11: =DATOS!B12 -> 73514426 | F11: Placa: | H11: =DATOS!B20 -> CYB612
B12: Dirección: | C12: =DATOS!B10 -> JR QUILCA 571 TDA 108 | F12: Kilometraje: | H12: =DATOS!B34 -> 1432
B13: Teléfono: | C13: =DATOS!B15 -> 931580291 | F13: Cilindrada: | H13: =DATOS!B23 -> 1.499
B14: REVISIONES
B15: 1. BATERIA DE ARRANQUE | F15: 2.DISTRIBUIDOR
B16: Voltaje batería(v) | F16: Condición del rotor
B17: Voltaje de arranque(v) | F17: Condición de la tapa
B18: Prueba de arranque(caída de voltaje(v)) | F18: Operación avance por vacío
B19: Estado de bornes | F19: Operación avance centrifugo
B20: 3. BOBINA/ CABLEADO /BUJIAS | F20: 4. SISTEMA DE CARBURACION-INYECCION
B21: Entrada a la bobina de arranque | F21: Verificación filtro de aire
B22: Entrada a la bobina de funcionamiento | F22: Verificación filtro de combustible
B23: Salida de la bobina y polaridad de la bobina | F23: Operación del carburador
B24: Condición de cables y bujías | F24: Operación del sistema de inyección
B25: 5. SISTEMA DE ADMISION | F25: 6. SISTEMA DE ESCAPE
B26: En mínimo a............rpm ..........pulgadas de Hg | F26: Verificación general estado y funcionamiento
... B30: Otros | F30: Otros
B31: 9. VERIFICACION DEL BALANCE Y COMPRESION DE CILINDROS
B32: NUMEROS DE CILINDROS | D32: 1 | E32: 2 | F32: 3 | G32: 4 | H32: 5 | I32: 6 | J32: 7 | K32: 8
B33: COMPRESION OBTENIDA (PSI)*
B34: PRUEBA DE ESTANQUEIDAD (%)
B35: *Para la prueba de compresión la diferencia máxima respecto a las especificaciones del fabricante debe ser 20% y entre cilindros del 10%.
B36: RESULTADO DE LAS REVISIONES
B37: OBSERVACIONES (reparaciones o refuerzos):
B40: =DATOS!B36 -> HENRY ALBERTO CHAVEZ MEDINA
B41: RESPONSABLE DE LA REVISION
B43: FECHA: | C43: 46060 | F43: V° B° | I43: CLIENTE
I44: N° DNI: | J44: =DATOS!B12 -> 73514426
B47: NOTA: EFECTUADA LA REVISION QUEDA A CRITERIO DEL INSTALADOR Y EL USUARIO LA INSTALACION DEL EQUIPO DE CONVERSION.

Sheet CARTILLA GNV
H31: FIRMA
G32: Nombre: | H32: =DATOS!B8 -> VASQUEZ VILLARREAL ALEX ANTONIO | J32: DNI/CE: | K32: =DATOS!B12 -> 73514426
G33: Correo electrónico: | H33: =DATOS!B35 -> alexvasquez112001@gmail.com | J33: Teléfono: | K33: =DATOS!B15 -> 931580291

Sheet CARTILLA GNV (2)
H8: FIRMA
G10: Nombre: | H10: =DATOS!B8 -> VASQUEZ VILLARREAL ALEX ANTONIO | J10: RUC: | K10: =DATOS!B12 -> 73514426
G11: Correo electrónico: | H11: =DATOS!B35 -> alexvasquez112001@gmail.com | J11: Teléfono: | K11: =DATOS!B15 -> 931580291

Sheet GARANTIA
K2: GARANTIA - GNV
K4: - TALLER CARRIGAS PERU E.I.R.L. le brinda un año de garantía para cualquier parte o repuesto que sea necesario en el EQUIPO INSTALADO, esto para el buen funcionamiento de su vehículo. - TALLER CARRIGAS PERU E.I.R.L. les otorga un mantenimiento preventivo a los 1500 kilómetros. - Está prohibida la manipulación del equipo GNV por personas no autorizadas y/o eventualidades que afecten al mismo, esto motivara la anulación automática de esta garantía. NOTA: Pasado el kilometraje dentro de la garantía no se harán revisiones adicionales, por lo tanto, el taller no asume ninguna responsabilidad.
A8: CERTIFICADO DE GARANTIA
A9: TALLER CARRIGAS EIRL
A10: DATOS DEL VEHICULO
A11: PLACA: | C11: =DATOS!B20 -> CYB612 | E11: MARCA: | G11: =DATOS!B16 -> JETOUR X50 | I11: KILOMETRAJE:
A12: AÑO: | C12: 2027 | E12: MODELO: | I12: =DATOS!B34 -> 1432
A13: CILINDRADA: | C13: =DATOS!B23 -> 1.499 | E13: SERIE/VIN: | G13: =DATOS!B46 -> LVTDB11BXVDC01245
A14: COMBUSTIBLE: | C14: =DATOS!B22 -> GASOLINA | E14: NR. REGISTRAL: | G14: =DATOS!B47 -> 55639535
A15: DATOS DEL USUARIO | K15: FICHA DE MANTENIMIENTO
K16: USUARIO: | M16: =DATOS!B8 -> VASQUEZ VILLARREAL ALEX ANTONIO
A17: NOMBRE: | C17: =DATOS!B8 -> VASQUEZ VILLARREAL ALEX ANTONIO | K17: EQUIPO: | M17: =DATOS!B31 -> TOMASETTO ACHILLE
A18: DNI/CE: | C18: =DATOS!B12 -> 73514426 | E18: TELEFONO: | G18: =DATOS!B15 -> 931580291 | K18: MANTENIMIENTO PREVENTIVO GRATUITO | N18: FECHA | Q18: OBSERVACIONES
A19: DIRECCION: | C19: =DATOS!B10 -> JR QUILCA 571 TDA 108
A20: FECHA DE INSTALACION: | E20: 46134 | K20: 1500 KM
K21: MANTENIMIENTO PREVENTIVO | N21: FECHA | Q21: OBSERVACIONES
A22: GARANTIA DEL TALLER | K22: 20 000 KM
A24: Por el presente documento garantizamos la buena calidad y funcionamiento de los equipos instalados en el vehículo por el periodo de 1 año. Cabe recalcar que la manipulación del equipo por alguna persona ajena al equipo de especialistas de nuestro taller durante este periodo, con llevara automáticamente a la anulación de la garantía. | K24: 50 000 KM
K26: 80 000 KM
A27: FECHA DE VENCIMIENTO DE LA GARANTIA: | G27: =DATOS!B45 -> 46499
A28: EL EQUIPO INSTALADO CONSTA DE LOS SIGUIENTES ELEMENTOS | K28: ¡HAZ EL MANTENIMIENTO DEL SISTEMA DE GAS AL MENOS 1 VEZ AL AÑO!
A29: DESCRIPCION | C29: MARCA | E29: MODELO | G29: CAPSD | H29: AÑO | I29: SERIE
A30: REDUCTOR | C30: =DATOS!B31 -> TOMASETTO ACHILLE | L30: TELEFONOS: 971 065 262
A31: CILINDRO 1 | C31: YA | E31: CILINDRICO | G31: =DATOS!B28 -> 28+28 | L31: CORREO: soportecarrigas@gmail.com
A32: CILINDRO 2 | E32: CILINDRICO | L32: DIRECCION: Av. Huancaray Mz. B1 Lt. 15 – Santa Anita.
